<?xml version="1.0" ?>

<robot name="popo" xmlns:xacro="http://www.ros.org/wiki/xacro">
  <material name="orange">
    <color rgba="84 211 0 1" />
  </material>
  <material name="red">
    <color rgba="77 5 232 1" />
  </material>
  <material name="malachita">
    <color rgba="64 0 230 1" />
  </material>
  <material name="electric_indigo">
    <color rgba="140 252 20 1" />
  </material>

  <link name="base_link">
      <visual>
        <origin rpy="0 0 0" xyz="0 0 0.225" />
        <geometry>
          <mesh filename="package://mrm2/meshes/Base_reduced.stl" scale="0.01 0.01 0.01" />
        </geometry>
        <material name="orange" />
      </visual>
  </link>
    
  <joint name="base_link__link_01" type="revolute">
    <axis xyz="0 0 1"/>
    <limit effort="1000.0" lower="-3.14" upper="3.14" velocity="0.5"/>
    <origin rpy="0 0 0" xyz="-0.386 0 0.425"/>
    <parent link="base_link"/>
    <child link="link_01"/>
  </joint>
    
  <link name="link_01">
      <visual>
        <origin rpy="0 0 0" xyz="0 0 0.1875" />
        <geometry>
          <mesh filename="package://mrm2/meshes/Link1_reduced.stl" scale="0.01 0.01 0.01" />
        </geometry>
        <material name="red" />
      </visual>
  </link>

  <joint name="link_01__link_02" type="revolute">
    <axis xyz="0 1 0"/>
    <limit effort="1000.0" lower="-3.14" upper="3.14" velocity="0.5"/>
    <origin rpy="0 0 0" xyz="0 0 0.2500431"/>
    <parent link="link_01"/>
    <child link="link_02"/>
  </joint>

  <link name="link_02">
      <visual>
        <origin rpy="0 0 0" xyz="0 0 0.58323" />
        <geometry>
          <mesh filename="package://mrm2/meshes/Link2_reduced.stl" scale="0.01 0.01 0.01" />
        </geometry>
        <material name="malachita" />
      </visual>
  </link>

  <joint name="link_02__link_03" type="revolute">
    <axis xyz="0 1 0"/>
    <limit effort="1000.0" lower="-3.14" upper="3.14" velocity="0.5"/>
    <origin rpy="0 0 0" xyz="0 0 1.073"/>
    <parent link="link_02"/>
    <child link="link_03"/>
  </joint>

  <link name="link_03">
      <visual>
        <origin rpy="0 0 0" xyz="-0.65 0 0" />
        <geometry>
          <mesh filename="package://mrm2/meshes/Link3_reduced.stl" scale="0.01 0.01 0.01" />
        </geometry>
        <material name="electric_indigo" />
      </visual>
  </link>

  <joint name="link_03__link_04" type="revolute">
    <axis xyz="0 1 0"/>
    <limit effort="1000.0" lower="-3.14" upper="3.14" velocity="0.5"/>
    <origin rpy="0 0 0" xyz="-1.287 0 0.057"/>
    <parent link="link_03"/>
    <child link="link_04"/>
  </joint>

  <link name="link_04">
      <visual>
        <origin rpy="0 0 0" xyz="-0.05 0 0" />
        <geometry>
          <mesh filename="package://mrm2/meshes/Link4_reduced.stl" scale="0.01 0.01 0.01" />
        </geometry>
        <material name="orange" />
      </visual>
  </link>

  <joint name="link_04__link_05" type="revolute">
    <axis xyz="1 0 0"/>
    <limit effort="1000.0" lower="-3.14" upper="3.14" velocity="0.5"/>
    <origin rpy="0 0 0" xyz="-0.4327 0 0"/>
    <parent link="link_04"/>
    <child link="link_05"/>
  </joint>

  <link name="link_05">
      <visual>
        <origin rpy="0 0 0" xyz="0 0.0005 0.0416" />
        <geometry>
          <mesh filename="package://mrm2/meshes/Link5_reduced.stl" scale="0.01 0.01 0.01" />
        </geometry>
        <material name="red" />
      </visual>
  </link>

  <joint name="link_05__gripper_01" type="revolute">
    <axis xyz="0 0 1"/>
    <limit effort="1000.0" lower="-3.14" upper="3.14" velocity="0.5"/>
    <origin rpy="0 0 0" xyz="0 -0.1225 -0.1605"/>
    <parent link="link_05"/>
    <child link="gripper_01"/>
  </joint>

  <link name="gripper_01">
      <visual>
        <origin rpy="0 0 0" xyz="-0.19 -0.04 0" />
        <geometry>
          <mesh filename="package://mrm2/meshes/Gripper1_reduced.stl" scale="0.01 0.01 0.01" />
        </geometry>
        <material name="malachita" />
      </visual>
  </link>

  <joint name="link_05__gripper_02" type="revolute">
    <axis xyz="0 0 1"/>
    <limit effort="1000.0" lower="-3.14" upper="3.14" velocity="0.5"/>
    <origin rpy="0 0 0" xyz="0 0.1225 -0.1605"/>
    <parent link="link_05"/>
    <child link="gripper_02"/>
  </joint>

  <link name="gripper_02">
      <visual>
        <origin rpy="0 0 0" xyz="-0.19 0.039 0" />
        <geometry>
          <mesh filename="package://mrm2/meshes/Gripper2_reduced.stl" scale="0.01 0.01 0.01" />
        </geometry>
        <material name="electric_indigo" />
      </visual>
  </link>

</robot>
